Traceback (most recent call last):

  File "C:\ProgramData\Anaconda3\lib\site-packages\pandas\core\internals\construction.py", line 564, in _list_to_arrays
    columns = _validate_or_indexify_columns(content, columns)

  File "C:\ProgramData\Anaconda3\lib\site-packages\pandas\core\internals\construction.py", line 688, in _validate_or_indexify_columns
    raise AssertionError(

AssertionError: 1 columns passed, passed data had 12 columns


The above exception was the direct cause of the following exception:

Traceback (most recent call last):

  File "C:\Users\2011747\Downloads\untitled0.py", line 431, in <module>
    run_text_analytics_chats(path=user_parameter_path, file_name=user_file)

  File "C:\Users\2011747\Downloads\untitled0.py", line 81, in wrapper
    result = func(*args, **kwargs)

  File "C:\Users\2011747\Downloads\untitled0.py", line 424, in run_text_analytics_chats
    pd.DataFrame.from_dict(file_log, orient='index', columns=['File_Name']).reset_index().to_csv(

  File "C:\ProgramData\Anaconda3\lib\site-packages\pandas\core\frame.py", line 1309, in from_dict
    return cls(data, index=index, columns=columns, dtype=dtype)

  File "C:\ProgramData\Anaconda3\lib\site-packages\pandas\core\frame.py", line 509, in __init__
    arrays, columns = to_arrays(data, columns, dtype=dtype)

  File "C:\ProgramData\Anaconda3\lib\site-packages\pandas\core\internals\construction.py", line 524, in to_arrays
    return _list_to_arrays(data, columns, coerce_float=coerce_float, dtype=dtype)

  File "C:\ProgramData\Anaconda3\lib\site-packages\pandas\core\internals\construction.py", line 567, in _list_to_arrays
    raise ValueError(e) from e

ValueError: 1 columns passed, passed data had 12 columns
