runfile('C:/Users/2011747/Downloads/untitled1.py', wdir='C:/Users/2011747/Downloads')
file 1 (out of 12) processing has started (file name: AnjliKaushik.Bajaria@sc.com.xlsx)
Traceback (most recent call last):

  File "C:\Users\2011747\Downloads\untitled1.py", line 426, in <module>
    run_text_analytics_chats(path=user_parameter_path, file_name=user_file)

  File "C:\Users\2011747\Downloads\untitled1.py", line 81, in wrapper
    result = func(*args, **kwargs)

  File "C:\Users\2011747\Downloads\untitled1.py", line 410, in run_text_analytics_chats
    save_final_processed_files(user_parameters=user_parameters, df_clean=df_clean, df_excluded=df_excluded,

  File "C:\Users\2011747\Downloads\untitled1.py", line 361, in save_final_processed_files
    pd.DataFrame.from_dict(log, orient='index', columns=['File_Name']).reset_index().to_excel(writer,

  File "C:\ProgramData\Anaconda3\lib\site-packages\pandas\core\frame.py", line 1299, in from_dict
    if isinstance(list(data.values())[0], (Series, dict)):

TypeError: 'numpy.ndarray' object is not callable
